<?xml version="1.0" ?>
<!-- =================================================================================== -->
<!-- |    This document was autogenerated by xacro from robot.xacro                    | -->
<!-- |    EDITING THIS FILE BY HAND IS NOT RECOMMENDED                                 | -->
<!-- =================================================================================== -->
<robot name="robot">

  <!--
  #########
  ######### COLORS
  #########
  -->
  <material name="black">
    <color rgba="0.0 0.0 0.0 1.0"/>
  </material>
  <material name="blue">
    <color rgba="0.0 0.0 0.8 1.0"/>
  </material>
  <material name="green">
    <color rgba="0.0 0.8 0.0 1.0"/>
  </material>
  <material name="grey">
    <color rgba="0.2 0.2 0.2 1.0"/>
  </material>
  <material name="silver">
    <color rgba="0.9137254901960784 0.9137254901960784 0.8470588235294118 1.0"/>
  </material>
  <material name="orange">
    <color rgba="1.0 0.4235294117647059 0.0392156862745098 1.0"/>
  </material>
  <material name="brown">
    <color rgba="0.8705882352941177 0.8117647058823529 0.7647058823529411 1.0"/>
  </material>
  <material name="red">
    <color rgba="0.8 0.0 0.0 1.0"/>
  </material>
  <material name="white">
    <color rgba="1.0 1.0 1.0 1.0"/>
  </material>
  <material name="aluminum">
    <color rgba="0.5 0.5 0.5 1"/>
  </material>
  <material name="plastic">
    <color rgba="0.1 0.1 0.1 1"/>
  </material>










  <!--
  #########
  ######### GO1 BODY
  #########
  -->
  <!-- TRUNK/BASE-->
  <link name="base">
    <visual>
      <origin rpy="0 0 0" xyz="0 0 0"/>
      <geometry>
        <box size="0.001 0.001 0.001"/>
      </geometry>
    </visual>
  </link>

  <joint name="floating_base" type="fixed">
    <origin rpy="0 0 0" xyz="0 0 0"/>
    <parent link="base"/>
    <child link="trunk"/>
  </joint>

  <link name="trunk">
    <visual>
      <origin rpy="0 0 0" xyz="0 0 0"/>
      <geometry>
        <mesh filename="../meshes/trunk.stl" scale="1 1 1"/>
      </geometry>
      <material name="aluminum"/>
    </visual>
    <collision>
      <origin rpy="0 0 0" xyz="0 0 0"/>
      <geometry>
        <box size="0.3762 0.0935 0.114"/>
      </geometry>
    </collision>
    <inertial>
      <origin rpy="0 0 0" xyz="0.0223 0.002 -0.0005"/>
      <mass value="5.204"/>
      <inertia ixx="0.0168128557" ixy="-0.0002296769" ixz="-0.0002945293" iyy="0.063009565" iyz="-4.18731e-05" izz="0.0716547275"/>
    </inertial>
  </link>










  <!-- IMU -->
  <!-- Imu is fixed to the base link -->
  <joint name="imu_joint" type="fixed">
    <origin rpy="0. 0. 0." xyz="0. 0. 0."/>
    <parent link="trunk"/>
    <child link="imu_link"/>
  </joint>

  <!-- Imu link -->
  <link name="imu_link">
    <inertial>
      <mass value="0.01"/>
      <origin rpy="0 0 0" xyz="0 0 0"/>
      <inertia ixx="0.000001" ixy="0" ixz="0" iyy="0.000001" iyz="0" izz="0.000001"/>
    </inertial>
    <visual>
      <origin rpy="0 0 0" xyz="0 0 0"/>
      <geometry>
        <box size="0.015 0.015 0.004"/>
      </geometry>
    </visual>
    <material name="blue"/>
  </link>









  <!--
  #########
  ######### GO1 JOINTS
  #########
  -->
  <joint name="FR_hip_joint" type="revolute">
    <origin rpy="0 0 0" xyz="0.1881 -0.04675 0"/>
    <parent link="trunk"/>
    <child link="FR_hip"/>
    <axis xyz="1 0 0"/>
    <dynamics damping="0.01" friction="0.0"/>
    <limit effort="23.7" lower="-0.863" upper="0.863" velocity="30.1"/>
  </joint>
  <link name="FR_hip">
    <visual>
      <origin rpy="3.141592653589793 0 0" xyz="0 0 0"/>
      <geometry>
        <mesh filename="../meshes/hip.stl" scale="1 1 1"/>
      </geometry>
      <material name="orange"/>
    </visual>
    <collision>
      <origin rpy="1.5707963267948966 0 0" xyz="0 0 0"/>
      <geometry>
        <cylinder length="0.04" radius="0.046"/>
      </geometry>
    </collision>
    <inertial>
      <origin rpy="0 0 0" xyz="-0.005657 0.008752 -0.000102"/>
      <mass value="0.591"/>
      <inertia ixx="0.000334008405" ixy="1.0826066e-05" ixz="1.290732e-06" iyy="0.000619101213" iyz="-1.643194e-06" izz="0.00040057614"/>
    </inertial>
  </link>
  <joint name="FR_thigh_joint" type="revolute">
    <origin rpy="0 0 0" xyz="0 -0.08 0"/>
    <parent link="FR_hip"/>
    <child link="FR_thigh"/>
    <axis xyz="0 1 0"/>
    <dynamics damping="0.01" friction="0.0"/>
    <limit effort="23.7" lower="-0.686" upper="4.501" velocity="30.1"/>
  </joint>
  <link name="FR_thigh">
    <visual>
      <origin rpy="0 0 0" xyz="0 0 0"/>
      <geometry>
        <mesh filename="../meshes/thigh_mirror.stl" scale="1 1 1"/>
      </geometry>
      <material name="orange"/>
    </visual>
    <collision>
      <origin rpy="0 1.5707963267948966 0" xyz="0 0 -0.1065"/>
      <geometry>
        <box size="0.213 0.0245 0.034"/>
      </geometry>
    </collision>
    <inertial>
      <origin rpy="0 0 0" xyz="-0.003342 0.018054 -0.033451"/>
      <mass value="0.92"/>
      <inertia ixx="0.004431760472" ixy="-5.7496807e-05" ixz="-0.000218457134" iyy="0.004485671726" iyz="-0.000572001265" izz="0.000740309489"/>
    </inertial>
  </link>
  <joint name="FR_calf_joint" type="revolute">
    <origin rpy="0 0 0" xyz="0 0 -0.213"/>
    <parent link="FR_thigh"/>
    <child link="FR_calf"/>
    <axis xyz="0 1 0"/>
    <dynamics damping="0.01" friction="0.0"/>
    <limit effort="35.55" lower="-2.818" upper="-0.888" velocity="20.06"/>
  </joint>
  <link name="FR_calf">
    <visual>
      <origin rpy="0 0 0" xyz="0 0 0"/>
      <geometry>
        <mesh filename="../meshes/calf.stl" scale="1 1 1"/>
      </geometry>
      <material name="orange"/>
    </visual>
    <collision>
      <origin rpy="0 1.5707963267948966 0" xyz="0 0 -0.1065"/>
      <geometry>
        <box size="0.213 0.016 0.016"/>
      </geometry>
    </collision>
    <inertial>
      <origin rpy="0 0 0" xyz="0.006197 0.001408 -0.116695"/>
      <mass value="0.135862"/>
      <inertia ixx="0.001088793059" ixy="-2.55679e-07" ixz="7.117814e-06" iyy="0.001100428748" iyz="2.077264e-06" izz="2.4787446e-05"/>
    </inertial>
  </link>
  <joint name="FR_foot_fixed" type="fixed" dont_collapse="true">
    <origin rpy="0 0 0" xyz="0 0 -0.213"/>
    <parent link="FR_calf"/>
    <child link="FR_foot"/>
  </joint>
  <link name="FR_foot">
    <visual>
      <origin rpy="0 0 0" xyz="0 0 0"/>
      <geometry>
        <sphere radius="0.01"/>
      </geometry>
      <material name="black"/>
    </visual>
    <collision>
      <origin rpy="0 0 0" xyz="0 0 0"/>
      <geometry>
        <sphere radius="0.02"/>
      </geometry>
    </collision>
    <inertial>
      <mass value="0.06"/>
      <inertia ixx="9.600000000000001e-06" ixy="0.0" ixz="0.0" iyy="9.600000000000001e-06" iyz="0.0" izz="9.600000000000001e-06"/>
    </inertial>
  </link>
  <joint name="FL_hip_joint" type="revolute">
    <origin rpy="0 0 0" xyz="0.1881 0.04675 0"/>
    <parent link="trunk"/>
    <child link="FL_hip"/>
    <axis xyz="1 0 0"/>
    <dynamics damping="0.01" friction="0.0"/>
    <limit effort="23.7" lower="-0.863" upper="0.863" velocity="30.1"/>
  </joint>
  <link name="FL_hip">
    <visual>
      <origin rpy="0 0 0" xyz="0 0 0"/>
      <geometry>
        <mesh filename="../meshes/hip.stl" scale="1 1 1"/>
      </geometry>
      <material name="orange"/>
    </visual>
    <collision>
      <origin rpy="1.5707963267948966 0 0" xyz="0 0 0"/>
      <geometry>
        <cylinder length="0.04" radius="0.046"/>
      </geometry>
    </collision>
    <inertial>
      <origin rpy="0 0 0" xyz="-0.005657 -0.008752 -0.000102"/>
      <mass value="0.591"/>
      <inertia ixx="0.000334008405" ixy="-1.0826066e-05" ixz="1.290732e-06" iyy="0.000619101213" iyz="1.643194e-06" izz="0.00040057614"/>
    </inertial>
  </link>
  <joint name="FL_thigh_joint" type="revolute">
    <origin rpy="0 0 0" xyz="0 0.08 0"/>
    <parent link="FL_hip"/>
    <child link="FL_thigh"/>
    <axis xyz="0 1 0"/>
    <dynamics damping="0.01" friction="0.0"/>
    <limit effort="23.7" lower="-0.686" upper="4.501" velocity="30.1"/>
  </joint>
  <link name="FL_thigh">
    <visual>
      <origin rpy="0 0 0" xyz="0 0 0"/>
      <geometry>
        <mesh filename="../meshes/thigh.stl" scale="1 1 1"/>
      </geometry>
      <material name="orange"/>
    </visual>
    <collision>
      <origin rpy="0 1.5707963267948966 0" xyz="0 0 -0.1065"/>
      <geometry>
        <box size="0.213 0.0245 0.034"/>
      </geometry>
    </collision>
    <inertial>
      <origin rpy="0 0 0" xyz="-0.003342 -0.018054 -0.033451"/>
      <mass value="0.92"/>
      <inertia ixx="0.004431760472" ixy="5.7496807e-05" ixz="-0.000218457134" iyy="0.004485671726" iyz="0.000572001265" izz="0.000740309489"/>
    </inertial>
  </link>
  <joint name="FL_calf_joint" type="revolute">
    <origin rpy="0 0 0" xyz="0 0 -0.213"/>
    <parent link="FL_thigh"/>
    <child link="FL_calf"/>
    <axis xyz="0 1 0"/>
    <dynamics damping="0.01" friction="0.0"/>
    <limit effort="35.55" lower="-2.818" upper="-0.888" velocity="20.06"/>
  </joint>
  <link name="FL_calf">
    <visual>
      <origin rpy="0 0 0" xyz="0 0 0"/>
      <geometry>
        <mesh filename="../meshes/calf.stl" scale="1 1 1"/>
      </geometry>
      <material name="orange"/>
    </visual>
    <collision>
      <origin rpy="0 1.5707963267948966 0" xyz="0 0 -0.1065"/>
      <geometry>
        <box size="0.213 0.016 0.016"/>
      </geometry>
    </collision>
    <inertial>
      <origin rpy="0 0 0" xyz="0.006197 0.001408 -0.116695"/>
      <mass value="0.135862"/>
      <inertia ixx="0.001088793059" ixy="-2.55679e-07" ixz="7.117814e-06" iyy="0.001100428748" iyz="2.077264e-06" izz="2.4787446e-05"/>
    </inertial>
  </link>
  <joint name="FL_foot_fixed" type="fixed" dont_collapse="true">
    <origin rpy="0 0 0" xyz="0 0 -0.213"/>
    <parent link="FL_calf"/>
    <child link="FL_foot"/>
  </joint>
  <link name="FL_foot">
    <visual>
      <origin rpy="0 0 0" xyz="0 0 0"/>
      <geometry>
        <sphere radius="0.01"/>
      </geometry>
      <material name="black"/>
    </visual>
    <collision>
      <origin rpy="0 0 0" xyz="0 0 0"/>
      <geometry>
        <sphere radius="0.02"/>
      </geometry>
    </collision>
    <inertial>
      <mass value="0.06"/>
      <inertia ixx="9.600000000000001e-06" ixy="0.0" ixz="0.0" iyy="9.600000000000001e-06" iyz="0.0" izz="9.600000000000001e-06"/>
    </inertial>
  </link>
  <joint name="RR_hip_joint" type="revolute">
    <origin rpy="0 0 0" xyz="-0.1881 -0.04675 0"/>
    <parent link="trunk"/>
    <child link="RR_hip"/>
    <axis xyz="1 0 0"/>
    <dynamics damping="0.01" friction="0.0"/>
    <limit effort="23.7" lower="-0.863" upper="0.863" velocity="30.1"/>
  </joint>
  <link name="RR_hip">
    <visual>
      <origin rpy="3.141592653589793 3.141592653589793 0" xyz="0 0 0"/>
      <geometry>
        <mesh filename="../meshes/hip.stl" scale="1 1 1"/>
      </geometry>
      <material name="orange"/>
    </visual>
    <collision>
      <origin rpy="1.5707963267948966 0 0" xyz="0 0 0"/>
      <geometry>
        <cylinder length="0.04" radius="0.046"/>
      </geometry>
    </collision>
    <inertial>
      <origin rpy="0 0 0" xyz="0.005657 0.008752 -0.000102"/>
      <mass value="0.591"/>
      <inertia ixx="0.000334008405" ixy="-1.0826066e-05" ixz="-1.290732e-06" iyy="0.000619101213" iyz="-1.643194e-06" izz="0.00040057614"/>
    </inertial>
  </link>
  <joint name="RR_thigh_joint" type="revolute">
    <origin rpy="0 0 0" xyz="0 -0.08 0"/>
    <parent link="RR_hip"/>
    <child link="RR_thigh"/>
    <axis xyz="0 1 0"/>
    <dynamics damping="0.01" friction="0.0"/>
    <limit effort="23.7" lower="-0.686" upper="4.501" velocity="30.1"/>
  </joint>
  <link name="RR_thigh">
    <visual>
      <origin rpy="0 0 0" xyz="0 0 0"/>
      <geometry>
        <mesh filename="../meshes/thigh_mirror.stl" scale="1 1 1"/>
      </geometry>
      <material name="orange"/>
    </visual>
    <collision>
      <origin rpy="0 1.5707963267948966 0" xyz="0 0 -0.1065"/>
      <geometry>
        <box size="0.213 0.0245 0.034"/>
      </geometry>
    </collision>
    <inertial>
      <origin rpy="0 0 0" xyz="-0.003342 0.018054 -0.033451"/>
      <mass value="0.92"/>
      <inertia ixx="0.004431760472" ixy="-5.7496807e-05" ixz="-0.000218457134" iyy="0.004485671726" iyz="-0.000572001265" izz="0.000740309489"/>
    </inertial>
  </link>
  <joint name="RR_calf_joint" type="revolute">
    <origin rpy="0 0 0" xyz="0 0 -0.213"/>
    <parent link="RR_thigh"/>
    <child link="RR_calf"/>
    <axis xyz="0 1 0"/>
    <dynamics damping="0.01" friction="0.0"/>
    <limit effort="35.55" lower="-2.818" upper="-0.888" velocity="20.06"/>
  </joint>
  <link name="RR_calf">
    <visual>
      <origin rpy="0 0 0" xyz="0 0 0"/>
      <geometry>
        <mesh filename="../meshes/calf.stl" scale="1 1 1"/>
      </geometry>
      <material name="orange"/>
    </visual>
    <collision>
      <origin rpy="0 1.5707963267948966 0" xyz="0 0 -0.1065"/>
      <geometry>
        <box size="0.213 0.016 0.016"/>
      </geometry>
    </collision>
    <inertial>
      <origin rpy="0 0 0" xyz="0.006197 0.001408 -0.116695"/>
      <mass value="0.135862"/>
      <inertia ixx="0.001088793059" ixy="-2.55679e-07" ixz="7.117814e-06" iyy="0.001100428748" iyz="2.077264e-06" izz="2.4787446e-05"/>
    </inertial>
  </link>
  <joint name="RR_foot_fixed" type="fixed" dont_collapse="true">
    <origin rpy="0 0 0" xyz="0 0 -0.213"/>
    <parent link="RR_calf"/>
    <child link="RR_foot"/>
  </joint>
  <link name="RR_foot">
    <visual>
      <origin rpy="0 0 0" xyz="0 0 0"/>
      <geometry>
        <sphere radius="0.01"/>
      </geometry>
      <material name="black"/>
    </visual>
    <collision>
      <origin rpy="0 0 0" xyz="0 0 0"/>
      <geometry>
        <sphere radius="0.02"/>
      </geometry>
    </collision>
    <inertial>
      <mass value="0.06"/>
      <inertia ixx="9.600000000000001e-06" ixy="0.0" ixz="0.0" iyy="9.600000000000001e-06" iyz="0.0" izz="9.600000000000001e-06"/>
    </inertial>
  </link>
  <joint name="RL_hip_joint" type="revolute">
    <origin rpy="0 0 0" xyz="-0.1881 0.04675 0"/>
    <parent link="trunk"/>
    <child link="RL_hip"/>
    <axis xyz="1 0 0"/>
    <dynamics damping="0.01" friction="0.0"/>
    <limit effort="23.7" lower="-0.863" upper="0.863" velocity="30.1"/>
  </joint>
  <link name="RL_hip">
    <visual>
      <origin rpy="0 3.141592653589793 0" xyz="0 0 0"/>
      <geometry>
        <mesh filename="../meshes/hip.stl" scale="1 1 1"/>
      </geometry>
      <material name="orange"/>
    </visual>
    <collision>
      <origin rpy="1.5707963267948966 0 0" xyz="0 0 0"/>
      <geometry>
        <cylinder length="0.04" radius="0.046"/>
      </geometry>
    </collision>
    <inertial>
      <origin rpy="0 0 0" xyz="0.005657 -0.008752 -0.000102"/>
      <mass value="0.591"/>
      <inertia ixx="0.000334008405" ixy="1.0826066e-05" ixz="-1.290732e-06" iyy="0.000619101213" iyz="1.643194e-06" izz="0.00040057614"/>
    </inertial>
  </link>
  <joint name="RL_thigh_joint" type="revolute">
    <origin rpy="0 0 0" xyz="0 0.08 0"/>
    <parent link="RL_hip"/>
    <child link="RL_thigh"/>
    <axis xyz="0 1 0"/>
    <dynamics damping="0.01" friction="0.0"/>
    <limit effort="23.7" lower="-0.686" upper="4.501" velocity="30.1"/>
  </joint>
  <link name="RL_thigh">
    <visual>
      <origin rpy="0 0 0" xyz="0 0 0"/>
      <geometry>
        <mesh filename="../meshes/thigh.stl" scale="1 1 1"/>
      </geometry>
      <material name="orange"/>
    </visual>
    <collision>
      <origin rpy="0 1.5707963267948966 0" xyz="0 0 -0.1065"/>
      <geometry>
        <box size="0.213 0.0245 0.034"/>
      </geometry>
    </collision>
    <inertial>
      <origin rpy="0 0 0" xyz="-0.003342 -0.018054 -0.033451"/>
      <mass value="0.92"/>
      <inertia ixx="0.004431760472" ixy="5.7496807e-05" ixz="-0.000218457134" iyy="0.004485671726" iyz="0.000572001265" izz="0.000740309489"/>
    </inertial>
  </link>
  <joint name="RL_calf_joint" type="revolute">
    <origin rpy="0 0 0" xyz="0 0 -0.213"/>
    <parent link="RL_thigh"/>
    <child link="RL_calf"/>
    <axis xyz="0 1 0"/>
    <dynamics damping="0.01" friction="0.0"/>
    <limit effort="35.55" lower="-2.818" upper="-0.888" velocity="20.06"/>
  </joint>
  <link name="RL_calf">
    <visual>
      <origin rpy="0 0 0" xyz="0 0 0"/>
      <geometry>
        <mesh filename="../meshes/calf.stl" scale="1 1 1"/>
      </geometry>
      <material name="orange"/>
    </visual>
    <collision>
      <origin rpy="0 1.5707963267948966 0" xyz="0 0 -0.1065"/>
      <geometry>
        <box size="0.213 0.016 0.016"/>
      </geometry>
    </collision>
    <inertial>
      <origin rpy="0 0 0" xyz="0.006197 0.001408 -0.116695"/>
      <mass value="0.135862"/>
      <inertia ixx="0.001088793059" ixy="-2.55679e-07" ixz="7.117814e-06" iyy="0.001100428748" iyz="2.077264e-06" izz="2.4787446e-05"/>
    </inertial>
  </link>
  <joint name="RL_foot_fixed" type="fixed" dont_collapse="true">
    <origin rpy="0 0 0" xyz="0 0 -0.213"/>
    <parent link="RL_calf"/>
    <child link="RL_foot"/>
  </joint>
  <link name="RL_foot">
    <visual>
      <origin rpy="0 0 0" xyz="0 0 0"/>
      <geometry>
        <sphere radius="0.01"/>
      </geometry>
      <material name="black"/>
    </visual>
    <collision>
      <origin rpy="0 0 0" xyz="0 0 0"/>
      <geometry>
        <sphere radius="0.02"/>
      </geometry>
    </collision>
    <inertial>
      <mass value="0.06"/>
      <inertia ixx="9.600000000000001e-06" ixy="0.0" ixz="0.0" iyy="9.600000000000001e-06" iyz="0.0" izz="9.600000000000001e-06"/>
    </inertial>
  </link>









  
  <!--
  #########
  ######### SENSORS
  #########
  -->
  <joint name="support_cameras_joint" type="fixed">
    <origin rpy="1.5707963267948966 0 -0.7853981633974483" xyz="0.218 0.0275 0.0505"/>
    <parent link="trunk"/>
    <child link="support_cameras"/>
  </joint>
  <link name="support_cameras">
    <visual>
      <geometry>
        <mesh filename="../sensors/double_camera_go1_head.stl" scale="0.001 0.001 0.001"/>
      </geometry>
      <material name="silver"/>
    </visual>
    <collision>
      <geometry>
        <mesh filename="../sensors/double_camera_go1_head.stl" scale="0.001 0.001 0.001"/>
      </geometry>
    </collision>
  </link>
  <!-- camera body, with origin at bottom screw mount -->
  <joint name="d455_joint" type="fixed">
    <origin rpy="0 0.26005405854715513 0" xyz="0.23 0.0 0.125"/>
    <parent link="trunk"/>
    <child link="d455_bottom_screw_frame"/>
  </joint>
  <link name="d455_bottom_screw_frame"/>
  <joint name="d455_link_joint" type="fixed">
    <origin rpy="0 0 0" xyz="0.011150000000000002 0.0475 0.0145"/>
    <parent link="d455_bottom_screw_frame"/>
    <child link="d455_link"/>
  </joint>
  <link name="d455_link">
    <visual>
      <origin rpy="1.5707963267948966 0 1.5707963267948966" xyz="0.0046500000000000005 -0.0475 0"/>
      <geometry>
        <mesh filename="../sensors/d455/d455.stl" scale="0.001 0.001 0.001"/>
      </geometry>
      <material name="silver"/>
    </visual>
    <collision>
      <origin rpy="0 0 0" xyz="-0.00845 -0.0475 0"/>
      <geometry>
        <box size="0.026 0.124 0.029"/>
      </geometry>
      <material name="orange"/>
    </collision>
    <inertial>
      <!-- The following are not reliable values, and should not be used for modeling -->
      <mass value="0.072"/>
      <origin xyz="0 0 0"/>
      <inertia ixx="0.003881243" ixy="0.0" ixz="0.0" iyy="0.000498940" iyz="0.0" izz="0.003879257"/>
    </inertial>
  </link>
  <!-- camera body -->
  <joint name="t265_joint" type="fixed">
    <origin rpy="0 0.0 0" xyz="0.24 0.0 0.10700000000000001"/>
    <parent link="trunk"/>
    <child link="t265_pose_frame"/>
  </joint>
  <link name="t265_pose_frame"/>
  <joint name="t265_link_joint" type="fixed">
    <origin rpy="0 0 0" xyz="0 0 0"/>
    <parent link="t265_pose_frame"/>
    <child link="t265_link"/>
  </joint>
  <link name="t265_link">
    <visual>
      <origin rpy="1.5707963267948966 0 1.5707963267948966" xyz="-0.00625 -0.054 -0.01275"/>
      <geometry>
        <mesh filename="../sensors/t265/t265.stl" scale="0.001 0.001 0.001"/>
      </geometry>
      <material name="silver"/>
    </visual>
    <collision>
      <geometry>
        <box size="0.0125 0.108 0.0255"/>
      </geometry>
    </collision>
  </link>
  <joint name="rplidar_base_joint" type="fixed">
    <origin rpy="0 0 0" xyz="0 0 0.19"/>
    <parent link="trunk"/>
    <child link="rplidar_base"/>
  </joint>
  <link name="rplidar_base">
    <visual>
      <!-- <origin xyz="0 0 -0.245" rpy="0 0 0"/> -->
      <!--coordinate frame aligned with laser beam -->
      <origin rpy="0 0 1.5707963267948966" xyz="0 0 -0.19"/>
      <geometry>
        <mesh filename="../sensors/rplidar/lidar_2d_go1.stl" scale="0.001 0.001 0.001"/>
      </geometry>
      <material name="black"/>
    </visual>
    <collision>
      <origin rpy="0 0 0" xyz="0 0 0.0325"/>
      <geometry>
        <cylinder length="0.065" radius="0.032"/>
      </geometry>
      <material name="black"/>
    </collision>
    <inertial>
      <origin rpy="0 0 0" xyz="0 0 0.0325"/>
      <mass value="0.321"/>
      <inertia ixx="0.00019519475000000003" ixy="0.0" ixz="0.0" iyy="0.00019519475000000003" iyz="0.0" izz="0.000164352"/>
    </inertial>
  </link>
  <joint name="rplidar_laser_joint" type="fixed">
    <origin rpy="0 0 0" xyz="0 0 0.055"/>
    <parent link="rplidar_base"/>
    <child link="rplidar_laser"/>
  </joint>
  <link name="rplidar_laser"/>
  <!-- 2D Laser gazebo plugin -->
  <joint name="backpack_joint" type="fixed">
    <origin rpy="0 0 1.5707963267948966" xyz="0.125 -0.071 0"/>
    <parent link="trunk"/>
    <child link="backpack"/>
  </joint>
  <link name="backpack">
    <visual>
      <geometry>
        <mesh filename="../sensors/backpack_go1.stl" scale="0.001 0.001 0.001"/>
      </geometry>
      <material name="aluminum"/>
    </visual>
    <collision>
      <origin rpy="0 0 -1.5707963267948966" xyz="0.071 0.125 0.127"/>
      <geometry>
        <box size="0.19 0.12 0.14"/>
      </geometry>
    </collision>
    <inertial>
      <origin rpy="0 0 -1.5707963267948966" xyz="0.071 0.125 0.127"/>
      <mass value="2.16"/>
      <inertia ixx="0.010026" ixy="0.0" ixz="0.0" iyy="0.0061200000000000004" iyz="0.0" izz="0.00909"/>
    </inertial>
  </link>
</robot>

